OrderBookSim/OrderBookSim/Outputs/Log1361625506.txt
0--INFO	Added rule
0--INFO	Added rule
0--INFO	Added rule
0--INFO	Added rule
1250--INFO	Enqueued order: Price: 2147483647.00, Volume: 3, Type: BUY, Market Order: 1, Participant: 114, Stock:[ID: 0, Symbol: GOOG], Time: 1250, OrderNumber: 0
1288--INFO	Enqueued order: Price: 2147483647.00, Volume: 922, Type: BUY, Market Order: 1, Participant: 108, Stock:[ID: 0, Symbol: GOOG], Time: 1288, OrderNumber: 1
1302--INFO	Enqueued order: Price: 2147483647.00, Volume: 29, Type: BUY, Market Order: 1, Participant: 26, Stock:[ID: 0, Symbol: GOOG], Time: 1302, OrderNumber: 2
1316--INFO	Enqueued order: Price: 0.00, Volume: 425, Type: SELL, Market Order: 1, Participant: 59, Stock:[ID: 0, Symbol: GOOG], Time: 1316, OrderNumber: 3
1317--INFO	Last Price Set:100.00
1317--INFO	Notified Traders of trade1317---Trade ID: 0, Price: 100.00, Volume: 3 between ID:[114] and ID:[59]
1317--INFO	Last Price Set:100.00
1317--INFO	Notified Traders of trade1317---Trade ID: 1, Price: 100.00, Volume: 422 between ID:[108] and ID:[59]
1346--INFO	Enqueued order: Price: 0.00, Volume: 125, Type: SELL, Market Order: 1, Participant: 32, Stock:[ID: 0, Symbol: GOOG], Time: 1346, OrderNumber: 4
1347--INFO	Last Price Set:100.00
1347--INFO	Notified Traders of trade1347---Trade ID: 2, Price: 100.00, Volume: 125 between ID:[108] and ID:[32]
1353--INFO	Enqueued order: Price: 0.00, Volume: 236, Type: SELL, Market Order: 1, Participant: 118, Stock:[ID: 0, Symbol: GOOG], Time: 1353, OrderNumber: 5
1354--INFO	Last Price Set:100.00
1354--INFO	Notified Traders of trade1354---Trade ID: 3, Price: 100.00, Volume: 236 between ID:[108] and ID:[118]
1415--INFO	Enqueued order: Price: 2147483647.00, Volume: 286, Type: BUY, Market Order: 1, Participant: 77, Stock:[ID: 0, Symbol: GOOG], Time: 1415, OrderNumber: 6
1440--INFO	Enqueued order: Price: 0.00, Volume: 98, Type: SELL, Market Order: 1, Participant: 97, Stock:[ID: 0, Symbol: GOOG], Time: 1440, OrderNumber: 7
1441--INFO	Last Price Set:100.00
1441--INFO	Notified Traders of trade1441---Trade ID: 4, Price: 100.00, Volume: 98 between ID:[108] and ID:[97]
1456--INFO	Enqueued order: Price: 2147483647.00, Volume: 589, Type: BUY, Market Order: 1, Participant: 24, Stock:[ID: 0, Symbol: GOOG], Time: 1456, OrderNumber: 8
1484--INFO	Enqueued order: Price: 2147483647.00, Volume: 452, Type: BUY, Market Order: 1, Participant: 34, Stock:[ID: 0, Symbol: GOOG], Time: 1484, OrderNumber: 9
1506--INFO	Enqueued order: Price: 2147483647.00, Volume: 817, Type: BUY, Market Order: 1, Participant: 10, Stock:[ID: 0, Symbol: GOOG], Time: 1506, OrderNumber: 10
1557--INFO	Enqueued order: Price: 2147483647.00, Volume: 866, Type: BUY, Market Order: 1, Participant: 80, Stock:[ID: 0, Symbol: GOOG], Time: 1557, OrderNumber: 11
1566--INFO	Enqueued order: Price: 2147483647.00, Volume: 865, Type: BUY, Market Order: 1, Participant: 101, Stock:[ID: 0, Symbol: GOOG], Time: 1566, OrderNumber: 12
1583--INFO	Enqueued order: Price: 2147483647.00, Volume: 510, Type: BUY, Market Order: 1, Participant: 22, Stock:[ID: 0, Symbol: GOOG], Time: 1583, OrderNumber: 13
1585--INFO	Enqueued order: Price: 100.05, Volume: 927, Type: SELL, Market Order: 0, Participant: 30, Stock:[ID: 0, Symbol: GOOG], Time: 1585, OrderNumber: 14
1586--INFO	Last Price Set:100.05
1586--INFO	Notified Traders of trade1586---Trade ID: 5, Price: 100.05, Volume: 922 between ID:[108] and ID:[30]
1586--INFO	Last Price Set:100.05
1586--INFO	Notified Traders of trade1586---Trade ID: 6, Price: 100.05, Volume: 5 between ID:[26] and ID:[30]
1611--INFO	Enqueued order: Price: 2147483647.00, Volume: 797, Type: BUY, Market Order: 1, Participant: 57, Stock:[ID: 0, Symbol: GOOG], Time: 1611, OrderNumber: 15
1622--INFO	Enqueued order: Price: 0.00, Volume: 216, Type: SELL, Market Order: 1, Participant: 39, Stock:[ID: 0, Symbol: GOOG], Time: 1622, OrderNumber: 16
1622--INFO	Enqueued order: Price: 2147483647.00, Volume: 649, Type: BUY, Market Order: 1, Participant: 123, Stock:[ID: 0, Symbol: GOOG], Time: 1622, OrderNumber: 17
1623--INFO	Last Price Set:100.05
1623--INFO	Notified Traders of trade1623---Trade ID: 7, Price: 100.05, Volume: 29 between ID:[26] and ID:[39]
1623--INFO	Last Price Set:100.05
1623--INFO	Notified Traders of trade1623---Trade ID: 8, Price: 100.05, Volume: 187 between ID:[77] and ID:[39]
1654--INFO	Enqueued order: Price: 2147483647.00, Volume: 868, Type: BUY, Market Order: 1, Participant: 1, Stock:[ID: 0, Symbol: GOOG], Time: 1654, OrderNumber: 18
1663--INFO	Enqueued order: Price: 2147483647.00, Volume: 422, Type: BUY, Market Order: 1, Participant: 91, Stock:[ID: 0, Symbol: GOOG], Time: 1663, OrderNumber: 19
1672--INFO	Enqueued order: Price: 0.00, Volume: 141, Type: SELL, Market Order: 1, Participant: 67, Stock:[ID: 0, Symbol: GOOG], Time: 1672, OrderNumber: 20
1673--INFO	Last Price Set:100.05
1673--INFO	Notified Traders of trade1673---Trade ID: 9, Price: 100.05, Volume: 141 between ID:[77] and ID:[67]
1695--INFO	Enqueued order: Price: 2147483647.00, Volume: 148, Type: BUY, Market Order: 1, Participant: 60, Stock:[ID: 0, Symbol: GOOG], Time: 1695, OrderNumber: 21
1721--INFO	Enqueued order: Price: 2147483647.00, Volume: 261, Type: BUY, Market Order: 1, Participant: 107, Stock:[ID: 0, Symbol: GOOG], Time: 1721, OrderNumber: 22
1729--INFO	Enqueued order: Price: 2147483647.00, Volume: 777, Type: BUY, Market Order: 1, Participant: 110, Stock:[ID: 0, Symbol: GOOG], Time: 1729, OrderNumber: 23
1731--INFO	Enqueued order: Price: 0.00, Volume: 27, Type: SELL, Market Order: 1, Participant: 15, Stock:[ID: 0, Symbol: GOOG], Time: 1731, OrderNumber: 24
1732--INFO	Last Price Set:100.05
1732--INFO	Notified Traders of trade1732---Trade ID: 10, Price: 100.05, Volume: 27 between ID:[77] and ID:[15]
1737--INFO	Enqueued order: Price: 2147483647.00, Volume: 704, Type: BUY, Market Order: 1, Participant: 75, Stock:[ID: 0, Symbol: GOOG], Time: 1737, OrderNumber: 25
1746--INFO	Enqueued order: Price: 2147483647.00, Volume: 621, Type: BUY, Market Order: 1, Participant: 25, Stock:[ID: 0, Symbol: GOOG], Time: 1746, OrderNumber: 26
1747--INFO	Enqueued order: Price: 2147483647.00, Volume: 818, Type: BUY, Market Order: 1, Participant: 28, Stock:[ID: 0, Symbol: GOOG], Time: 1747, OrderNumber: 27
1788--INFO	Enqueued order: Price: 0.00, Volume: 140, Type: SELL, Market Order: 1, Participant: 127, Stock:[ID: 0, Symbol: GOOG], Time: 1788, OrderNumber: 28
1789--INFO	Last Price Set:100.05
1789--INFO	Notified Traders of trade1789---Trade ID: 11, Price: 100.05, Volume: 140 between ID:[77] and ID:[127]
1809--INFO	Enqueued order: Price: 2147483647.00, Volume: 397, Type: BUY, Market Order: 1, Participant: 13, Stock:[ID: 0, Symbol: GOOG], Time: 1809, OrderNumber: 29
1861--INFO	Enqueued order: Price: 0.00, Volume: 928, Type: SELL, Market Order: 1, Participant: 14, Stock:[ID: 0, Symbol: GOOG], Time: 1861, OrderNumber: 30
1862--INFO	Last Price Set:100.05
1862--INFO	Notified Traders of trade1862---Trade ID: 12, Price: 100.05, Volume: 286 between ID:[77] and ID:[14]
1862--INFO	Last Price Set:100.05
1862--INFO	Notified Traders of trade1862---Trade ID: 13, Price: 100.05, Volume: 589 between ID:[24] and ID:[14]
1862--INFO	Last Price Set:100.05
1862--INFO	Notified Traders of trade1862---Trade ID: 14, Price: 100.05, Volume: 53 between ID:[34] and ID:[14]
1874--INFO	Enqueued order: Price: 0.00, Volume: 397, Type: SELL, Market Order: 1, Participant: 81, Stock:[ID: 0, Symbol: GOOG], Time: 1874, OrderNumber: 31
1875--INFO	Last Price Set:100.05
1875--INFO	Notified Traders of trade1875---Trade ID: 15, Price: 100.05, Volume: 397 between ID:[34] and ID:[81]
1889--INFO	Enqueued order: Price: 0.00, Volume: 33, Type: SELL, Market Order: 1, Participant: 5, Stock:[ID: 0, Symbol: GOOG], Time: 1889, OrderNumber: 32
1890--INFO	Last Price Set:100.05
1890--INFO	Notified Traders of trade1890---Trade ID: 16, Price: 100.05, Volume: 33 between ID:[34] and ID:[5]
1938--INFO	Enqueued order: Price: 2147483647.00, Volume: 143, Type: BUY, Market Order: 1, Participant: 88, Stock:[ID: 0, Symbol: GOOG], Time: 1938, OrderNumber: 33
